[2024-10-13T15:37:03.040+0000] {taskinstance.py:1157} INFO - Dependencies all met for dep_context=non-requeueable deps ti=<TaskInstance: etl_reddit_pipeline.reddit_extraction manual__2024-10-13T15:37:02.058839+00:00 [queued]>
[2024-10-13T15:37:03.043+0000] {taskinstance.py:1157} INFO - Dependencies all met for dep_context=requeueable deps ti=<TaskInstance: etl_reddit_pipeline.reddit_extraction manual__2024-10-13T15:37:02.058839+00:00 [queued]>
[2024-10-13T15:37:03.043+0000] {taskinstance.py:1359} INFO - Starting attempt 1 of 1
[2024-10-13T15:37:03.048+0000] {taskinstance.py:1380} INFO - Executing <Task(PythonOperator): reddit_extraction> on 2024-10-13 15:37:02.058839+00:00
[2024-10-13T15:37:03.051+0000] {standard_task_runner.py:57} INFO - Started process 80 to run task
[2024-10-13T15:37:03.052+0000] {standard_task_runner.py:84} INFO - Running: ['airflow', 'tasks', 'run', 'etl_reddit_pipeline', 'reddit_extraction', 'manual__2024-10-13T15:37:02.058839+00:00', '--job-id', '15', '--raw', '--subdir', 'DAGS_FOLDER/reddit_dag.py', '--cfg-path', '/tmp/tmpxbdmcoaf']
[2024-10-13T15:37:03.053+0000] {standard_task_runner.py:85} INFO - Job 15: Subtask reddit_extraction
[2024-10-13T15:37:03.072+0000] {task_command.py:415} INFO - Running <TaskInstance: etl_reddit_pipeline.reddit_extraction manual__2024-10-13T15:37:02.058839+00:00 [running]> on host f28f66444a85
[2024-10-13T15:37:03.255+0000] {taskinstance.py:1660} INFO - Exporting env vars: AIRFLOW_CTX_DAG_OWNER='Yunus Emre KORKMAZ' AIRFLOW_CTX_DAG_ID='etl_reddit_pipeline' AIRFLOW_CTX_TASK_ID='reddit_extraction' AIRFLOW_CTX_EXECUTION_DATE='2024-10-13T15:37:02.058839+00:00' AIRFLOW_CTX_TRY_NUMBER='1' AIRFLOW_CTX_DAG_RUN_ID='manual__2024-10-13T15:37:02.058839+00:00'
[2024-10-13T15:37:03.256+0000] {logging_mixin.py:151} INFO - connected to reddit!
[2024-10-13T15:37:04.383+0000] {taskinstance.py:1935} ERROR - Task failed with exception
Traceback (most recent call last):
  File "/home/airflow/.local/lib/python3.9/site-packages/pandas/core/indexes/base.py", line 3790, in get_loc
    return self._engine.get_loc(casted_key)
  File "index.pyx", line 152, in pandas._libs.index.IndexEngine.get_loc
  File "index.pyx", line 181, in pandas._libs.index.IndexEngine.get_loc
  File "pandas/_libs/hashtable_class_helper.pxi", line 7080, in pandas._libs.hashtable.PyObjectHashTable.get_item
  File "pandas/_libs/hashtable_class_helper.pxi", line 7088, in pandas._libs.hashtable.PyObjectHashTable.get_item
KeyError: 'upvote_ratio'

The above exception was the direct cause of the following exception:

Traceback (most recent call last):
  File "/home/airflow/.local/lib/python3.9/site-packages/airflow/operators/python.py", line 192, in execute
    return_value = self.execute_callable()
  File "/home/airflow/.local/lib/python3.9/site-packages/airflow/operators/python.py", line 209, in execute_callable
    return self.python_callable(*self.op_args, **self.op_kwargs)
  File "/opt/airflow/pipelines/reddit_pipeline.py", line 12, in reddit_pipeline
    post_df = transform_data(post_df)
  File "/opt/airflow/etls/reddit_etl.py", line 44, in transform_data
    post_df['upvote_ratio'] = post_df['upvote_ratio'].astype(int)
  File "/home/airflow/.local/lib/python3.9/site-packages/pandas/core/frame.py", line 3896, in __getitem__
    indexer = self.columns.get_loc(key)
  File "/home/airflow/.local/lib/python3.9/site-packages/pandas/core/indexes/base.py", line 3797, in get_loc
    raise KeyError(key) from err
KeyError: 'upvote_ratio'
[2024-10-13T15:37:04.400+0000] {taskinstance.py:1398} INFO - Marking task as FAILED. dag_id=etl_reddit_pipeline, task_id=reddit_extraction, execution_date=20241013T153702, start_date=20241013T153703, end_date=20241013T153704
[2024-10-13T15:37:04.408+0000] {standard_task_runner.py:104} ERROR - Failed to execute job 15 for task reddit_extraction ('upvote_ratio'; 80)
[2024-10-13T15:37:04.432+0000] {local_task_job_runner.py:228} INFO - Task exited with return code 1
[2024-10-13T15:37:04.445+0000] {taskinstance.py:2776} INFO - 0 downstream tasks scheduled from follow-on schedule check
